File: 6to_semestre/trabajos/python_/regrecion_young/datos.csv
Strain,Stress (MPa)
0,0
2.28E-06,0.258803489
4.56E-06,0.517606977
6.84E-06,0.776410466
9.13E-06,1.035213954
1.14E-05,1.294017443
1.37E-05,1.552820932
1.60E-05,1.81162442
1.83E-05,2.070427909
2.05E-05,2.329231397
2.28E-05,2.588034886
2.40E-05,2.933379897
2.51E-05,3.278724907
2.62E-05,3.624069918
2.74E-05,3.969414928
2.85E-05,4.314759939
2.97E-05,4.66010495
3.08E-05,5.00544996
3.19E-05,5.350794971
3.31E-05,5.696139981
3.42E-05,6.041484992
3.65E-05,6.386665787
3.88E-05,6.731846582
4.11E-05,7.077027377
4.33E-05,7.422208172
4.56E-05,7.767388968
4.79E-05,8.112569763
5.02E-05,8.457750558
5.25E-05,8.802931353
5.48E-05,9.148112148
5.70E-05,9.493292943
6.05E-05,10.05425279
6.39E-05,10.61521263
6.73E-05,11.17617248
7.07E-05,11.73713233
7.41E-05,12.29809217
7.76E-05,12.85905202
8.10E-05,13.42001186
8.44E-05,13.98097171
8.78E-05,14.54193155
9.13E-05,15.1028914
9.35E-05,15.49126085
9.58E-05,15.8796303
9.81E-05,16.26799975
0.00010038,16.6563692
0.000102661,17.04473865
0.000104943,17.43310809
0.000107224,17.82147754
0.000109505,18.20984699
0.000111787,18.59821644
0.000114068,18.98658589
0.000115209,19.20236494
0.000116349,19.41814399
0.00011749,19.63392304
0.000118631,19.84970209
0.000119772,20.06548114
0.000120912,20.28126019
0.000122053,20.49703924
0.000123194,20.71281829
0.000124334,20.92859734
0.000125475,21.14437639
0.000127756,21.53274584
0.000130038,21.92111529
0.000132319,22.30948474
0.000134601,22.69785419
0.000136882,23.08622364
0.000139163,23.47459308
0.000141445,23.86296253
0.000143726,24.25133198
0.000146008,24.63970143
0.000148289,25.02807088
0.00015057,25.33006302
0.000152852,25.63205516
0.000155133,25.93404731
0.000157415,26.23603945
0.000159696,26.53803159
0.000161977,26.84002373
0.000164259,27.14201587
0.00016654,27.44400802
0.000168822,27.74600016
0.000171103,28.0479923
0.000173384,28.52273906
0.000175666,28.99748581
0.000177947,29.47223257
0.000180228,29.94697932
0.00018251,30.42172608
0.000184791,30.89647283
0.000187072,31.37121959
0.000189353,31.84596634
0.000191635,32.3207131
0.000193916,32.79545985
0.000196197,33.1838293
0.000198479,33.57219875
0.00020076,33.96056819
0.000203042,34.34893764
0.000205323,34.73730709
0.000207604,35.12567654
0.000209886,35.51404599
0.000212167,35.90241543
0.000214449,36.29078488
0.00021673,36.67915433
0.000219011,36.98114647
0.000221293,37.28313861
0.000223574,37.58513076
0.000225856,37.8871229
0.000228137,38.18911504
0.000230418,38.49110718
0.0002327,38.79309932
0.000234981,39.09509147
0.000237263,39.39708361
0.000239544,39.69907575
0.000241825,40.04425654
0.000244107,40.38943734
0.000246388,40.73461814
0.000248669,41.07979893
0.000250951,41.42497973
0.000253232,41.77016052
0.000255513,42.11534132
0.000257794,42.46052211
0.000260076,42.80570291
0.000262357,43.1508837
0.000263498,43.49622871
0.000264638,43.84157372
0.000265779,44.18691873
0.00026692,44.53226374
0.000268061,44.87760875
0.000269201,45.22295376
0.000270342,45.56829877
0.000271483,45.91364378
0.000272623,46.25898879
0.000273764,46.6043338
0.000276045,46.99270325
0.000278327,47.3810727
0.000280608,47.76944215
0.00028289,48.1578116
0.000285171,48.54618105
0.000287452,48.93455049
0.000289734,49.32291994
0.000292015,49.71128939
0.000294297,50.09965884
0.000296578,50.48802829
0.000298859,50.83320909
0.000301141,51.17838988
0.000303422,51.52357068
0.000305704,51.86875147
0.000307985,52.21393227
0.000310266,52.55911306
0.000312548,52.90429386
0.000314829,53.24947465
0.000317111,53.59465545
0.000319392,53.93983624
0.000320533,54.2419926
0.000321673,54.54414895
0.000322814,54.84630531
0.000323954,55.14846167
0.000325095,55.45061803
0.000326236,55.75277438
0.000327376,56.05493074
0.000328517,56.3570871
0.000329657,56.65924345
0.000330798,56.96139981
0.000333079,57.30658061
0.000335361,57.6517614
0.000337642,57.9969422
0.000339924,58.34212299
0.000342205,58.68730379
0.000344486,59.03248458
0.000346768,59.37766538
0.000349049,59.72284617
0.000351331,60.06802697
0.000353612,60.41320776
0.000355893,60.67201125
0.000358175,60.93081474
0.000360456,61.18961823
0.000362738,61.44842172
0.000365019,61.70722521
0.0003673,61.96602869
0.000369582,62.22483218
0.000371863,62.48363567
0.000374145,62.74243916
0.000376426,63.00124265
0.000378707,63.43280075
0.000380989,63.86435885
0.00038327,64.29591696
0.000385552,64.72747506
0.000387833,65.15903316
0.000390114,65.59059126
0.000392396,66.02214936
0.000394677,66.45370747
0.000396959,66.88526557
0.00039924,67.31682367
0.000400381,67.66216868
0.000401521,68.00751369
0.000402662,68.3528587
0.000403802,68.69820371
0.000404943,69.04354872
0.000406084,69.38889373
0.000407224,69.73423874
0.000408365,70.07958375
0.000409505,70.42492876
0.000410646,70.77027377
0.000414068,71.20166766
0.00041749,71.63306154
0.000420912,72.06445543
0.000424334,72.49584931
0.000427757,72.9272432
0.000431179,73.35863709
0.000434601,73.79003097
0.000438023,74.22142486
0.000441445,74.65281874
0.000444867,75.08421263
0.000446008,75.38636899
0.000447148,75.68852535
0.000448289,75.9906817
0.00044943,76.29283806
0.000450571,76.59499442
0.000451711,76.89715078
0.000452852,77.19930714
0.000453993,77.50146349
0.000455133,77.80361985
0.000456274,78.10577621
0.000458555,78.40776835
0.000460837,78.70976049
0.000463118,79.01175264
0.000465399,79.31374478
0.000467681,79.61573692
0.000469962,79.91772906
0.000472243,80.2197212
0.000474524,80.52171335
0.000476806,80.82370549
0.000479087,81.12569763
0.000481368,81.47087843
0.00048365,81.81605922
0.000485931,82.16124002
0.000488213,82.50642081
0.000490494,82.85160161
0.000492775,83.1967824
0.000495057,83.5419632
0.000497338,83.88714399
0.00049962,84.23232478
0.000501901,84.57750558
0.000503042,84.87966194
0.000504182,85.18181829
0.000505323,85.48397465
0.000506464,85.78613101
0.000507605,86.08828737
0.000508745,86.39044372
0.000509886,86.69260008
0.000511027,86.99475644
0.000512167,87.29691279
0.000513308,87.59906915
0.000515589,87.85787264
0.000517871,88.11667613
0.000520152,88.37547962
0.000522434,88.63428311
0.000524715,88.8930866
0.000526996,89.15189008
0.000529278,89.41069357
0.000531559,89.66949706
0.000533841,89.92830055
0.000536122,90.18710404
0.000538403,90.57547349
0.000540685,90.96384294
0.000542966,91.35221238
0.000545247,91.74058183
0.000547529,92.12895128
0.00054981,92.51732073
0.000552091,92.90569018
0.000554372,93.29405962
0.000556654,93.68242907
0.000558935,94.07079852
0.000561216,94.37279066
0.000563498,94.6747828
0.000565779,94.97677495
0.000568061,95.27876709
0.000570342,95.58075923
0.000572623,95.88275137
0.000574905,96.18474351
0.000577186,96.48673566
0.000579468,96.7887278
0.000581749,97.09071994
0.00058289,97.3928763
0.00058403,97.69503265
0.000585171,97.99718901
0.000586312,98.29934536
0.000587453,98.60150172
0.000588593,98.90365808
0.000589734,99.20581443
0.000590875,99.50797079
0.000592015,99.81012714
0.000593156,100.1122835
0.000594297,100.3712512
0.000595437,100.6302189
0.000596578,100.8891866
0.000597719,101.1481543
0.000598859,101.4071221
0.0006,101.6660898
0.000601141,101.9250575
0.000602282,102.1840252
0.000603422,102.4429929
0.000604563,102.7019606
0.000605704,102.9177397
0.000606844,103.1335187
0.000607985,103.3492978
0.000609126,103.5650768
0.000610267,103.7808559
0.000611407,103.9966349
0.000612548,104.212414
0.000613689,104.428193
0.000614829,104.6439721
0.00061597,104.8597511
0.000618251,105.2049319
0.000620533,105.5501127
0.000622814,105.8952935
0.000625095,106.2404743
0.000627377,106.5856551
0.000629658,106.9308358
0.000631939,107.2760166
0.00063422,107.6211974
0.000636502,107.9663782
0.000638783,108.311559
0.000641064,108.5703625
0.000643346,108.829166
0.000645627,109.0879695
0.000647909,109.346773
0.00065019,109.6055765
0.000652471,109.8643799
0.000654753,110.1231834
0.000657034,110.3819869
0.000659316,110.6407904
0.000661597,110.8995939
0.000663878,111.1583974
0.00066616,111.4172009
0.000668441,111.6760044
0.000670723,111.9348079
0.000673004,112.1936114
0.000675285,112.4524148
0.000677567,112.7112183
0.000679848,112.9700218
0.00068213,113.2288253
0.000684411,113.4876288
0.000686692,113.7032436
0.000688974,113.9188585
0.000691255,114.1344733
0.000693536,114.3500881
0.000695818,114.565703
0.000698099,114.7813178
0.00070038,114.9969326
0.000702661,115.2125474
0.000704943,115.4281623
0.000707224,115.6437771
0.000709505,115.8593919
0.000711787,116.0750068
0.000714068,116.2906216
0.00071635,116.5062365
0.000718631,116.7218513
0.000720912,116.9374661
0.000723194,117.153081
0.000725475,117.3686958
0.000727757,117.5843107
0.000730038,117.7999255
0.000732319,118.0155403
0.000734601,118.2311552
0.000736882,118.44677
0.000739164,118.6623848
0.000741445,118.8779996
0.000743726,119.0936145
0.000746008,119.3092293
0.000748289,119.5248441
0.000750571,119.740459
0.000752852,119.9560738
0.000756274,120.1715244
0.000759696,120.386975
0.000763118,120.6024257
0.00076654,120.8178763
0.000769962,121.0333269
0.000773384,121.2487775
0.000776806,121.4642281
0.000780228,121.6796788
0.00078365,121.8951294
0.000787072,122.11058
0.000790494,122.3260306
0.000793916,122.5414812
0.000797338,122.7569319
0.00080076,122.9723825
0.000804183,123.1878331
0.000807605,123.4032837
0.000811027,123.6187343
0.000814449,123.834185
0.000817871,124.0496356
0.000821293,124.2650862
0.000824715,124.4805368
0.000828137,124.6959874
0.000831559,124.9114381
0.000834981,125.1268887
0.000838403,125.3423393
0.000841825,125.5577899
0.000845247,125.7732405
0.000848669,125.9886912
0.000852091,126.2041418
0.000855513,126.4195924
0.000858935,126.5486657
0.000862357,126.677739
0.000865779,126.8068124
0.000869201,126.9358857
0.000872624,127.064959
0.000876046,127.1940323
0.000879468,127.3231056
0.00088289,127.452179
0.000886312,127.5812523
0.000889734,127.7103256
0.000892015,127.8827518
0.000894297,128.055178
0.000896578,128.2276041
0.00089886,128.4000303
0.000901141,128.5724565
0.000903422,128.7448827
0.000905704,128.9173089
0.000907985,129.089735
0.000910267,129.2621612
0.000912548,129.4345874
0.00091597,129.6068494
0.000919392,129.7791113
0.000922814,129.9513733
0.000926236,130.1236353
0.000929658,130.2958973
0.00093308,130.4681592
0.000936502,130.6404212
0.000939924,130.8126832
0.000943346,130.9849451
0.000946768,131.1572071
0.000951331,131.3724935
0.000955893,131.5877799
0.000960456,131.8030663
0.000965019,132.0183527
0.000969582,132.2336391
0.000974144,132.4489255
0.000978707,132.6642119
0.00098327,132.8794983
0.000987832,133.0947847
0.000992395,133.3100711
0.000996958,133.5253575
0.001001521,133.7406439
0.001006083,133.9559303
0.001010646,134.1712167
0.001015209,134.3865032
0.001019772,134.6017896
0.001024335,134.817076
0.001028897,135.0323624
0.00103346,135.2476488
0.001038023,135.4629352
0.001041445,135.6351972
0.001044867,135.8074591
0.001048289,135.9797211
0.001051711,136.151983
0.001055133,136.324245
0.001058555,136.496507
0.001061977,136.6687689
0.001065399,136.8410309
0.001068821,137.0132928
0.001072243,137.1855548
0.001076806,137.3144639
0.001081369,137.443373
0.001085931,137.5722821
0.001090494,137.7011912
0.001095057,137.8301003
0.00109962,137.9590094
0.001104183,138.0879185
0.001108745,138.2168276
0.001113308,138.3457367
0.001117871,138.4746458
0.001122434,138.6899322
0.001126996,138.9052186
0.001131559,139.120505
0.001136122,139.3357914
0.001140685,139.5510779
0.001145247,139.7663643
0.00114981,139.9816507
0.001154373,140.1969371
0.001158935,140.4122235
0.001163498,140.6275099
0.001168061,140.756419
0.001172623,140.8853281
0.001177186,141.0142372
0.001181749,141.1431463
0.001186312,141.2720554
0.001190874,141.4009644
0.001195437,141.5298735
0.0012,141.6587826
0.001204562,141.7876917
0.001209125,141.9166008
0.001212547,142.0456741
0.001215969,142.1747474
0.001219391,142.3038208
0.001222813,142.4328941
0.001226236,142.5619674
0.001229658,142.6910407
0.00123308,142.820114
0.001236502,142.9491874
0.001239924,143.0782607
0.001243346,143.207334
0.001246768,143.3364073
0.00125019,143.4654806
0.001253612,143.5945539
0.001257034,143.7236272
0.001260457,143.8527006
0.001263879,143.9817739
0.001267301,144.1108472
0.001270723,144.2399205
0.001274145,144.3689938
0.001277567,144.4980671
0.00128213,144.6269762
0.001286692,144.7558853
0.001291255,144.8847944
0.001295818,145.0137035
0.001300381,145.1426126
0.001304943,145.2715217
0.001309506,145.4004308
0.001314069,145.5293399
0.001318631,145.658249
0.001323194,145.7871581
0.001328897,145.915903
0.001334601,146.0446479
0.001340304,146.1733927
0.001346008,146.3021376
0.001351711,146.4308825
0.001357414,146.5596274
0.001363118,146.6883723
0.001368821,146.8171171
0.001374525,146.945862
0.001380228,147.0746069
0.001385931,147.2465404
0.001391635,147.418474
0.001397338,147.5904075
0.001403042,147.7623411
0.001408745,147.9342746
0.001414448,148.1062081
0.001420152,148.2781417
0.001425855,148.4500752
0.001431559,148.6220088
0.001437262,148.7939423
0.001441825,148.8796627
0.001446388,148.9653832
0.00145095,149.0511036
0.001455513,149.1368241
0.001460076,149.2225445
0.001464639,149.3082649
0.001469202,149.3939854
0.001473764,149.4797058
0.001478327,149.5654263
0.00148289,149.6511467
0.001487453,149.7368672
0.001492015,149.8225876
0.001496578,149.9083081
0.001501141,149.9940285
0.001505704,150.079749
0.001510266,150.1654694
0.001514829,150.2511899
0.001519392,150.3369103
0.001523954,150.4226308
0.001528517,150.5083512
0.001531939,150.6374245
0.001535361,150.7664978
0.001538783,150.8955711
0.001542205,151.0246444
0.001545628,151.1537178
0.00154905,151.2827911
0.001552472,151.4118644
0.001555894,151.5409377
0.001559316,151.670011
0.001562738,151.7990843
0.001567301,151.8848048
0.001571863,151.9705252
0.001576426,152.0562457
0.001580989,152.1419661
0.001585551,152.2276866
0.001590114,152.313407
0.001594677,152.3991275
0.00159924,152.4848479
0.001603802,152.5705684
0.001608365,152.6562888
0.001612928,152.7420092
0.00161749,152.8277297
0.001622053,152.9134501
0.001626616,152.9991706
0.001631179,153.084891
0.001635741,153.1706114
0.001640304,153.2563319
0.001644867,153.3420523
0.001649429,153.4277728
0.001653992,153.5134932
0.001659696,153.5990494
0.001665399,153.6846057
0.001671103,153.7701619
0.001676806,153.8557181
0.00168251,153.9412744
0.001688213,154.0268306
0.001693917,154.1123868
0.00169962,154.197943
0.001705323,154.2834993
0.001711027,154.3690555
0.00171559,154.4547759
0.001720152,154.5404964
0.001724715,154.6262168
0.001729278,154.7119373
0.001733841,154.7976577
0.001738403,154.8833781
0.001742966,154.9690986
0.001747529,155.054819
0.001752091,155.1405395
0.001756654,155.2262599
0.001763498,155.3116519
0.001770342,155.3970439
0.001777186,155.482436
0.00178403,155.567828
0.001790875,155.65322
0.001797719,155.738612
0.001804563,155.824004
0.001811407,155.9093961
0.001818251,155.9947881
0.001825095,156.0801801
0.001829658,156.1659005
0.00183422,156.251621
0.001838783,156.3373414
0.001843346,156.4230619
0.001847909,156.5087823
0.001852471,156.5945027
0.001857034,156.6802232
0.001861597,156.7659436
0.001866159,156.8516641
0.001870722,156.9373845
0.001876426,157.0229407
0.001882129,157.108497
0.001887833,157.1940532
0.001893536,157.2796094
0.00189924,157.3651657
0.001904943,157.4507219
0.001910647,157.5362781
0.00191635,157.6218343
0.001922054,157.7073906
0.001927757,157.7929468
0.00193346,157.878503
0.001939164,157.9640593
0.001944867,158.0496155
0.001950571,158.1351717
0.001956274,158.220728
0.001961977,158.3062842
0.001967681,158.3918404
0.001973384,158.4773966
0.001979088,158.5629529
0.001984791,158.6485091
0.001989354,158.7342296
0.001993916,158.81995
0.001998479,158.9056705
0.002003042,158.9913909
0.002007605,159.0771114
0.002012167,159.1628318
0.00201673,159.2485523
0.002021293,159.3342727
0.002025855,159.4199932
0.002030418,159.5057136
0.002036121,159.5480812
0.002041825,159.5904487
0.002047528,159.6328163
0.002053232,159.6751839
0.002058935,159.7175515
0.002064638,159.759919
0.002070342,159.8022866
0.002076045,159.8446542
0.002081749,159.8870217
0.002087452,159.9293893
0.002093156,160.0149455
0.002098859,160.1005018
0.002104563,160.186058
0.002110266,160.2716142
0.00211597,160.3571705
0.002121673,160.4427267
0.002127377,160.5282829
0.00213308,160.6138391
0.002138784,160.6993954
0.002144487,160.7849516
0.002151331,160.827155
0.002158175,160.8693583
0.002165019,160.9115617
0.002171863,160.953765
0.002178708,160.9959684
0.002185552,161.0381718
0.002192396,161.0803751
0.00219924,161.1225785
0.002206084,161.1647818
0.002212928,161.2069852
0.002218631,161.2493528
0.002224335,161.2917204
0.002230038,161.3340879
0.002235742,161.3764555
0.002241445,161.4188231
0.002247148,161.4611907
0.002252852,161.5035583
0.002258555,161.5459258
0.002264259,161.5882934
0.002269962,161.630661
0.002275665,161.6730286
0.002281369,161.7153962
0.002287072,161.7577637
0.002292776,161.8001313
0.002298479,161.8424989
0.002304182,161.8848665
0.002309886,161.9272341
0.002315589,161.9696016
0.002321293,162.0119692
0.002326996,162.0543368
0.00233384,162.1397288
0.002340684,162.2251208
0.002347528,162.3105128
0.002354372,162.3959048
0.002361217,162.4812968
0.002368061,162.5666889
0.002374905,162.6520809
0.002381749,162.7374729
0.002388593,162.8228649
0.002395437,162.9082569
0.002402281,162.9504603
0.002409125,162.9926636
0.002415969,163.034867
0.002422813,163.0770703
0.002429657,163.1192737
0.002436502,163.1614771
0.002443346,163.2036804
0.00245019,163.2458838
0.002457034,163.2880871
0.002463878,163.3302905
0.002470722,163.4156825
0.002477566,163.5010745
0.00248441,163.5864665
0.002491254,163.6718585
0.002498099,163.7572505
0.002504943,163.8426426
0.002511787,163.9280346
0.002518631,164.0134266
0.002525475,164.0988186
0.002532319,164.1842106
0.002539163,164.226414
0.002546007,164.2686173
0.002552851,164.3108207
0.002559695,164.3530241
0.00256654,164.3952275
0.002573384,164.4374308
0.002580228,164.4796342
0.002587072,164.5218376
0.002593916,164.5640409
0.00260076,164.6062443
0.002609886,164.6913079
0.002619011,164.7763715
0.002628137,164.861435
0.002637262,164.9464986
0.002646387,165.0315622
0.002655513,165.1166258
0.002664639,165.2016894
0.002673764,165.2867529
0.002682889,165.3718165
0.002692015,165.4568801
0.0027,165.4989192
0.002707985,165.5409584
0.002715969,165.5829975
0.002723954,165.6250367
0.002731939,165.6670758
0.002739924,165.7091149
0.002747909,165.7511541
0.002755893,165.7931932
0.002763878,165.8352324
0.002771863,165.8772715
0.002777566,165.9196391
0.00278327,165.9620067
0.002788973,166.0043742
0.002794677,166.0467418
0.00280038,166.0891094
0.002806083,166.131477
0.002811787,166.1738446
0.00281749,166.2162121
0.002823194,166.2585797
0.002828897,166.3009473
0.002835741,166.3863393
0.002842585,166.4717313
0.002849429,166.5571233
0.002856273,166.6425153
0.002863118,166.7279074
0.002869962,166.8132994
0.002876806,166.8986914
0.00288365,166.9840834
0.002890494,167.0694754
0.002897338,167.1548674
0.002906464,167.1535537
0.002915589,167.15224
0.002924715,167.1509262
0.00293384,167.1496125
0.002942966,167.1482988
0.002952091,167.1469851
0.002961216,167.1456714
0.002970342,167.1443576
0.002979468,167.1430439
0.002988593,167.1417302
0.002995437,167.1839336
0.003002281,167.2261369
0.003009125,167.2683403
0.003015969,167.3105436
0.003022814,167.352747
0.003029658,167.3949504
0.003036502,167.4371537
0.003043346,167.4793571
0.00305019,167.5215604
0.003057034,167.5637638
0.00306616,167.6056387
0.003075285,167.6475137
0.003084411,167.6893886
0.003093536,167.7312635
0.003102662,167.7731385
0.003111787,167.8150134
0.003120912,167.8568883
0.003130038,167.8987632
0.003139164,167.9406382
0.003148289,167.9825131
0.003155133,168.0247165
0.003161977,168.0669198
0.003168821,168.1091232
0.003175665,168.1513265
0.003182509,168.1935299
0.003189354,168.2357333
0.003196198,168.2779366
0.003203042,168.32014
0.003209886,168.3623433
0.00321673,168.4045467
0.003223574,168.4467501
0.003230418,168.4889534
0.003237262,168.5311568
0.003244106,168.5733601
0.003250951,168.6155635
0.003257795,168.6577669
0.003264639,168.6999702
0.003271483,168.7421736
0.003278327,168.7843769
0.003285171,168.8265803
0.003293156,168.8686194
0.003301141,168.9106586
0.003309125,168.9526978
0.00331711,168.9947369
0.003325095,169.0367761
0.00333308,169.0788152
0.003341065,169.1208544
0.003349049,169.1628935
0.003357034,169.2049327
0.003365019,169.2469718
0.003370722,169.2461507
0.003376426,169.2453296
0.003382129,169.2445086
0.003387833,169.2436875
0.003393536,169.2428664
0.003399239,169.2420453
0.003404943,169.2412242
0.003410646,169.2404032
0.00341635,169.2395821
0.003422053,169.238761
0.003427756,169.2811286
0.00343346,169.3234962
0.003439163,169.3658637
0.003444867,169.4082313
0.00345057,169.4505989
0.003456273,169.4929665
0.003461977,169.5353341
0.00346768,169.5777016
0.003473384,169.6200692
0.003479087,169.6624368
0.003487072,169.6612873
0.003495057,169.6601378
0.003503041,169.6589883
0.003511026,169.6578388
0.003519011,169.6566893
0.003526996,169.6555397
0.003534981,169.6543902
0.003542965,169.6532407
0.00355095,169.6520912
0.003558935,169.6509417
0.003568061,169.6928166
0.003577186,169.7346916
0.003586312,169.7765665
0.003595437,169.8184414
0.003604563,169.8603164
0.003613688,169.9021913
0.003622814,169.9440662
0.003631939,169.9859411
0.003641065,170.0278161
0.00365019,170.069691
0.003659316,170.1115659
0.003668441,170.1534409
0.003677567,170.1953158
0.003686692,170.2371907
0.003695818,170.2790657
0.003704943,170.3209406
0.003714069,170.3628155
0.003723194,170.4046904
0.00373232,170.4465654
0.003741445,170.4884403
0.003748289,170.487455
0.003755133,170.4864697
0.003761977,170.4854844
0.003768821,170.4844991
0.003775666,170.4835139
0.00378251,170.4825286
0.003789354,170.4815433
0.003796198,170.480558
0.003803042,170.4795727
0.003809886,170.4785874
0.003817871,170.5206265
0.003825856,170.5626657
0.00383384,170.6047048
0.003841825,170.646744
0.00384981,170.6887831
0.003857795,170.7308222
0.00386578,170.7728614
0.003873764,170.8149005
0.003881749,170.8569397
0.003889734,170.8989788
0.003897719,170.941018
0.003905704,170.9830571
0.003913688,171.0250963
0.003921673,171.0671354
0.003929658,171.1091746
0.003937643,171.1512137
0.003945628,171.1932529
0.003953612,171.235292
0.003961597,171.2773312
0.003969582,171.3193703
0.003976426,171.3615737
0.00398327,171.403777
0.003990114,171.4459804
0.003996958,171.4881837
0.004003803,171.5303871
0.004010647,171.5725905
0.004017491,171.6147938
0.004024335,171.6569972
0.004031179,171.6992005
0.004038023,171.7414039
0.004046008,171.783443
0.004053993,171.8254822
0.004061977,171.8675213
0.004069962,171.9095605
0.004077947,171.9515996
0.004085932,171.9936387
0.004093917,172.0356779
0.004101901,172.077717
0.004109886,172.1197562
0.004117871,172.1617953
0.004128137,172.1603174
0.004138403,172.1588394
0.004148669,172.1573615
0.004158935,172.1558836
0.004169202,172.1544057
0.004179468,172.1529277
0.004189734,172.1514498
0.0042,172.1499719
0.004210266,172.1484939
0.004220532,172.147016
0.004228517,172.2322438
0.004236502,172.3174716
0.004244486,172.4026994
0.004252471,172.4879272
0.004260456,172.573155
0.004268441,172.6583827
0.004276426,172.7436105
0.00428441,172.8288383
0.004292395,172.9140661
0.00430038,172.9992939
0.004311787,172.9976518
0.004323194,172.9960096
0.004334601,172.9943675
0.004346008,172.9927253
0.004357415,172.9910832
0.004368821,172.989441
0.004380228,172.9877989
0.004391635,172.9861567
0.004403042,172.9845146
0.004414449,172.9828724
0.004424715,173.0677718
0.004434981,173.1526711
0.004445247,173.2375705
0.004455513,173.3224699
0.00446578,173.4073693
0.004476046,173.4922686
0.004486312,173.577168
0.004496578,173.6620674
0.004506844,173.7469667
0.00451711,173.8318661
0.004528517,173.8302239
0.004539924,173.8285818
0.004551331,173.8269396
0.004562738,173.8252975
0.004574145,173.8236553
0.004585551,173.8220131
0.004596958,173.820371
0.004608365,173.8187288
0.004619772,173.8170867
0.004631179,173.8154445
0.004642586,173.9001797
0.004653993,173.9849148
0.004665399,174.06965
0.004676806,174.1543851
0.004688213,174.2391203
0.00469962,174.3238555
0.004711027,174.4085906
0.004722433,174.4933258
0.00473384,174.5780609
0.004745247,174.6627961
0.004752091,174.6618108
0.004758935,174.6608255
0.004765779,174.6598402
0.004772623,174.6588549
0.004779468,174.6578696
0.004786312,174.6568843
0.004793156,174.655899
0.0048,174.6549137
0.004806844,174.6539284
0.004813688,174.6529431
0.004820532,174.7383351
0.004827376,174.8237271
0.00483422,174.9091192
0.004841064,174.9945112
0.004847908,175.0799032
0.004854753,175.1652952
0.004861597,175.2506872
0.004868441,175.3360793
0.004875285,175.4214713
0.004882129,175.5068633
0.004893536,175.5052211
0.004904943,175.503579
0.00491635,175.5019368
0.004927757,175.5002947
0.004939164,175.4986525
0.00495057,175.4970103
0.004961977,175.4953682
0.004973384,175.493726
0.004984791,175.4920839
0.004996198,175.4904417
0.005003042,175.5758337
0.005009886,175.6612257
0.00501673,175.7466178
0.005023574,175.8320098
0.005030419,175.9174018
0.005037263,176.0027938
0.005044107,176.0881858
0.005050951,176.1735779
0.005057795,176.2589699
0.005064639,176.3443619
0.005071483,176.3433766
0.005078327,176.3423913
0.005085171,176.341406
0.005092015,176.3404207
0.00509886,176.3394354
0.005105704,176.3384501
0.005112548,176.3374648
0.005119392,176.3364795
0.005126236,176.3354942
0.00513308,176.3345089
0.005141065,176.3765481
0.00514905,176.4185872
0.005157034,176.4606264
0.005165019,176.5026655
0.005173004,176.5447047
0.005180989,176.5867438
0.005188974,176.628783
0.005196958,176.6708221
0.005204943,176.7128613
0.005212928,176.7549004
0.005220913,176.7969396
0.005228898,176.8389787
0.005236882,176.8810179
0.005244867,176.923057
0.005252852,176.9650962
0.005260837,177.0071353
0.005268822,177.0491744
0.005276806,177.0912136
0.005284791,177.1332528
0.005292776,177.1752919
0.005301901,177.2171668
0.005311027,177.2590418
0.005320152,177.3009167
0.005329278,177.3427916
0.005338403,177.3846666
0.005347528,177.4265415
0.005356654,177.4684164
0.005365779,177.5102913
0.005374905,177.5521663
0.00538403,177.5940412
0.005392015,177.6360803
0.0054,177.6781195
0.005407984,177.7201586
0.005415969,177.7621978
0.005423954,177.8042369
0.005431939,177.846276
0.005439924,177.8883152
0.005447908,177.9303543
0.005455893,177.9723935
0.005463878,178.0144326
0.005471863,178.0564718
0.005479848,178.0985109
0.005487832,178.1405501
0.005495817,178.1825892
0.005503802,178.2246284
0.005511787,178.2666675
0.005519772,178.3087066
0.005527756,178.3507458
0.005535741,178.392785
0.005543726,178.4348241
0.005553992,178.4765348
0.005564258,178.5182455
0.005574525,178.5599562
0.005584791,178.6016669
0.005595057,178.6433777
0.005605323,178.6850884
0.005615589,178.7267991
0.005625856,178.7685098
0.005636122,178.8102205
0.005646388,178.8519312
0.005654373,178.8939704
0.005662358,178.9360095
0.005670342,178.9780487
0.005678327,179.0200878
0.005686312,179.062127
0.005694297,179.1041661
0.005702282,179.1462052
0.005710266,179.1882444
0.005718251,179.2302836
0.005726236,179.2723227
0.005734221,179.2711732
0.005742206,179.2700237
0.00575019,179.2688742
0.005758175,179.2677247
0.00576616,179.2665752
0.005774145,179.2654256
0.00578213,179.2642761
0.005790114,179.2631266
0.005798099,179.2619771
0.005806084,179.2608276
0.005814069,179.2596781
0.005822054,179.2585286
0.005830038,179.2573791
0.005838023,179.2562296
0.005846008,179.2550801
0.005853993,179.2539305
0.005861978,179.252781
0.005869962,179.2516315
0.005877947,179.250482
0.005885932,179.2493325
0.005890495,179.2918643
0.005895057,179.3343961
0.00589962,179.3769279
0.005904183,179.4194597
0.005908746,179.4619915
0.005913308,179.5045232
0.005917871,179.547055
0.005922434,179.5895868
0.005926996,179.6321186
0.005931559,179.6746504
0.005937262,179.6738293
0.005942966,179.6730082
0.005948669,179.6721872
0.005954373,179.6713661
0.005960076,179.670545
0.005965779,179.6697239
0.005971483,179.6689028
0.005977186,179.6680818
0.00598289,179.6672607
0.005986692,179.6667133